<mujoco model="GR1T1">
  <compiler angle="radian" meshdir="../meshes"/>
  <option timestep="0.001"/>
  <asset>
    <mesh name="base" file="base.STL"/>
    <mesh name="l_thigh_roll" file="l_thigh_roll.STL"/>
    <mesh name="l_thigh_yaw" file="l_thigh_yaw.STL"/>
    <mesh name="l_thigh_pitch" file="l_thigh_pitch.STL"/>
    <mesh name="l_shank_pitch" file="l_shank_pitch.STL"/>
    <mesh name="l_foot_pitch" file="l_foot_pitch.STL"/>
    <mesh name="l_foot_roll" file="l_foot_roll.STL"/>
    <mesh name="r_thigh_roll" file="r_thigh_roll.STL"/>
    <mesh name="r_thigh_yaw" file="r_thigh_yaw.STL"/>
    <mesh name="r_thigh_pitch" file="r_thigh_pitch.STL"/>
    <mesh name="r_shank_pitch" file="r_shank_pitch.STL"/>
    <mesh name="r_foot_pitch" file="r_foot_pitch.STL"/>
    <mesh name="r_foot_roll" file="r_foot_roll.STL"/>
    <mesh name="waist_yaw" file="waist_yaw.STL"/>
    <mesh name="waist_pitch" file="waist_pitch.STL"/>
    <mesh name="waist_roll" file="waist_roll.STL"/>
    <mesh name="head_yaw" file="head_yaw.STL"/>
    <mesh name="head_roll" file="head_roll.STL"/>
    <mesh name="head_pitch" file="head_pitch.STL"/>
    <mesh name="l_upper_arm_pitch" file="l_upper_arm_pitch.STL"/>
    <mesh name="l_upper_arm_roll" file="l_upper_arm_roll.STL"/>
    <mesh name="l_upper_arm_yaw" file="l_upper_arm_yaw.STL"/>
    <mesh name="l_lower_arm_pitch" file="l_lower_arm_pitch.STL"/>
    <mesh name="l_hand_yaw" file="l_hand_yaw.STL"/>
    <mesh name="l_hand_roll" file="l_hand_roll.STL"/>
    <mesh name="l_hand_pitch" file="l_hand_pitch.STL"/>
    <mesh name="r_upper_arm_pitch" file="r_upper_arm_pitch.STL"/>
    <mesh name="r_upper_arm_roll" file="r_upper_arm_roll.STL"/>
    <mesh name="r_upper_arm_yaw" file="r_upper_arm_yaw.STL"/>
    <mesh name="r_lower_arm_pitch" file="r_lower_arm_pitch.STL"/>
    <mesh name="r_hand_yaw" file="r_hand_yaw.STL"/>
    <mesh name="r_hand_roll" file="r_hand_roll.STL"/>
    <mesh name="r_hand_pitch" file="r_hand_pitch.STL"/>
  </asset>
  <worldbody>
    <light name="spotlight" mode="targetbodycom" target="base" pos="0 -1 2"/>
    <body name="base" pos="0 0 1.0">
      <!-- <camera name="track" pos="0 -3 1" zaxis="0 -1 0.5" mode="track"/> -->
      <inertial pos="-0.0508888 0.000109183 -0.0455794" quat="0.706855 0.707166 0.0123661 -0.0109307" mass="6.45117" diaginertia="0.0149302 0.0127972 0.00640923"/>
      <freejoint/>
      <geom type="mesh" contype="0" conaffinity="0" group="1" density="0" rgba="0.752941 0.752941 0.752941 1" mesh="base"/>
      <geom size="0.039 0.145" pos="0 0 -0.06" quat="0.707388 0.706825 0 0" type="cylinder" rgba="0.752941 0.752941 0.752941 1"/>
      <site name="imu" pos="0 0 0"/>
      <body name="l_thigh_roll" pos="-0.047999 0.105 -0.057493">
        <inertial pos="0.04163 3.4568e-05 -0.0021382" quat="0.575529 0.581908 -0.40597 0.406619" mass="1.1437" diaginertia="0.00117548 0.00100413 0.000943892"/>
        <joint name="l_hip_roll" pos="0 0 0" axis="1 0 1.221e-05" range="-0.09 0.79"/>
        <geom type="mesh" contype="0" conaffinity="0" group="1" density="0" rgba="0.75294 0.75294 0.75294 1" mesh="l_thigh_roll"/>
        <body name="l_thigh_yaw" pos="0.048 0 -0.030499">
          <inertial pos="0.00018348 0.046462 -0.10389" quat="0.704251 -0.0226446 -0.0453749 0.708138" mass="3.9888" diaginertia="0.0163385 0.0100158 0.00924336"/>
          <joint name="l_hip_yaw" pos="0 0 0" axis="1.2209e-05 6.8349e-05 1" range="-0.7 0.7"/>
          <geom type="mesh" contype="0" conaffinity="0" group="1" density="0" rgba="0.75294 0.75294 0.75294 1" mesh="l_thigh_yaw"/>
          <body name="l_thigh_pitch" pos="0 0 -0.11">
            <inertial pos="0.0028493 -0.021688 -0.090886" quat="0.707411 -0.0125435 -0.0111264 0.706604" mass="6.369" diaginertia="0.0532352 0.0425096 0.0134363"/>
            <joint name="l_hip_pitch" pos="0 0 0" axis="0 1 -6.8349e-05" range="-1.75 0.7"/>
            <geom type="mesh" contype="0" conaffinity="0" group="1" density="0" rgba="0.75294 0.75294 0.75294 1" mesh="l_thigh_pitch"/>
            <geom size="0.05 0.175" pos="0 0 -0.15" type="cylinder" rgba="0.75294 0.75294 0.75294 1"/>
            <body name="l_shank_pitch" pos="0 2.4606e-05 -0.36">
              <inertial pos="0.0024312 -2.9945e-05 -0.11554" quat="0.692137 0.00134576 0.00140217 0.721764" mass="2.1895" diaginertia="0.0162703 0.016117 0.00113627"/>
              <joint name="l_knee_pitch" pos="0 0 0" axis="0 1 6.8349e-05" range="-0.09 1.92"/>
              <geom type="mesh" contype="0" conaffinity="0" group="1" density="0" rgba="0.75294 0.75294 0.75294 1" mesh="l_shank_pitch"/>
              <geom size="0.05 0.1" pos="0 0 -0.15" type="cylinder" rgba="0.75294 0.75294 0.75294 1"/>
              <body name="l_foot_pitch" pos="0 2.3239e-05 -0.34">
                <inertial pos="1.748e-11 4.3804e-11 0" quat="1 3.42295e-05 -6.07362e-06 -2.07897e-10" mass="0.080335" diaginertia="5.1022e-06 4.3976e-06 4.188e-06"/>
                <joint name="l_ankle_pitch" pos="0 0 0" axis="0 1 6.8349e-05" range="-1.05 0.52"/>
                <geom type="mesh" contype="0" conaffinity="0" group="1" density="0" rgba="0.75294 0.75294 0.75294 1" mesh="l_foot_pitch"/>
                <body name="l_foot_roll">
                  <inertial pos="0.039446 0.00035757 -0.038101" quat="-0.00087198 0.709539 -0.00177594 0.704664" mass="0.584" diaginertia="0.00271032 0.0024027 0.000369145"/>
                  <joint name="l_ankle_roll" pos="0 0 0" axis="1 0 1.221e-05" range="-0.44 0.44"/>
                  <geom type="mesh" contype="0" conaffinity="0" group="1" density="0" rgba="0.75294 0.75294 0.75294 1" mesh="l_foot_roll"/>
                  <geom name="l_foot_1" size="0.02 0.12" pos="0.05 0.02 -0.035" quat="0.707105 0 0.707108 0" type="cylinder" rgba="0.75294 0.75294 0.75294 1"/>
                  <geom name="l_foot_2" size="0.02 0.12" pos="0.05 -0.02 -0.035" quat="0.707105 0 0.707108 0" type="cylinder" rgba="0.75294 0.75294 0.75294 1"/>
                  
                  <!-- <geom name="l_foot_1" size="0.001 0.04 0.02" pos="-0.05 0.0 -0.035" type="box" rgba="0.75294 0.75294 0.75294 1"/>
                  <geom name="l_foot_2" size="0.001 0.04 0.02" pos="0.15 0.0 -0.035" type="box" rgba="0.75294 0.75294 0.75294 1"/> -->

                </body>
              </body>
            </body>
          </body>
        </body>
      </body>
      <body name="r_thigh_roll" pos="-0.047999 -0.105 -0.057508">
        <inertial pos="0.0416295 3.45678e-05 -0.00213824" quat="0.57555 0.581927 -0.405942 0.406589" mass="1.14367" diaginertia="0.00117548 0.00100417 0.000943891"/>
        <joint name="r_hip_roll" pos="0 0 0" axis="1 0 1.221e-05" range="-0.79 0.09"/>
        <geom type="mesh" contype="0" conaffinity="0" group="1" density="0" rgba="0.752941 0.752941 0.752941 1" mesh="r_thigh_roll"/>
        <body name="r_thigh_yaw" pos="0.048 0 -0.030499">
          <inertial pos="-0.00159762 -0.0464482 -0.103899" quat="0.709186 -0.0420808 -0.0194028 0.703497" mass="3.98882" diaginertia="0.0163388 0.0100142 0.00924469"/>
          <joint name="r_hip_yaw" pos="0 0 0" axis="1.2209e-05 6.8349e-05 1" range="-0.7 0.7"/>
          <geom type="mesh" contype="0" conaffinity="0" group="1" density="0" rgba="0.752941 0.752941 0.752941 1" mesh="r_thigh_yaw"/>
          <body name="r_thigh_pitch" pos="0 0 -0.11">
            <inertial pos="0.002842 0.0217009 -0.0919987" quat="0.706586 -0.0113774 -0.0126258 0.707423" mass="6.36895" diaginertia="0.0532349 0.0424818 0.0134641"/>
            <joint name="r_hip_pitch" pos="0 0 0" axis="0 1 6.8349e-05" range="-1.75 0.7"/>
            <geom type="mesh" contype="0" conaffinity="0" group="1" density="0" rgba="0.752941 0.752941 0.752941 1" mesh="r_thigh_pitch"/>
            <geom size="0.05 0.175" pos="0 0 -0.15" type="cylinder" rgba="0.752941 0.752941 0.752941 1"/>
            <body name="r_shank_pitch" pos="0 2.4606e-05 -0.36">
              <inertial pos="0.00236658 4.56188e-05 -0.115532" quat="0.71872 0.00154106 0.00120241 0.695296" mass="2.18947" diaginertia="0.0162708 0.0161183 0.00113536"/>
              <joint name="r_knee_pitch" pos="0 0 0" axis="0 1 -6.8349e-05" range="-0.09 1.92"/>
              <geom type="mesh" contype="0" conaffinity="0" group="1" density="0" rgba="0.752941 0.752941 0.752941 1" mesh="r_shank_pitch"/>
              <geom size="0.05 0.1" pos="0 0 -0.15" type="cylinder" rgba="0.752941 0.752941 0.752941 1"/>
              <body name="r_foot_pitch" pos="0 2.3239e-05 -0.34">
                <inertial pos="1.75705e-11 4.40342e-11 0" quat="1 3.42336e-05 -6.07409e-06 -2.07938e-10" mass="0.0799219" diaginertia="5.11122e-06 4.40004e-06 4.17954e-06"/>
                <joint name="r_ankle_pitch" pos="0 0 0" axis="0 1 6.8349e-05" range="-1.05 0.52"/>
                <geom type="mesh" contype="0" conaffinity="0" group="1" density="0" rgba="0.752941 0.752941 0.752941 1" mesh="r_foot_pitch"/>
                <body name="r_foot_roll">
                  <inertial pos="0.043909 -0.00032475 -0.039419" quat="0.000727105 0.710094 0.00155959 0.704104" mass="0.58089" diaginertia="0.00280098 0.0024886 0.000368482"/>
                  <joint name="r_ankle_roll" pos="0 0 0" axis="1 0 1.221e-05" range="-0.44 0.44"/>
                  <geom type="mesh" contype="0" conaffinity="0" group="1" density="0" rgba="0.75294 0.75294 0.75294 1" mesh="r_foot_roll"/>
                  <geom name="r_foot_1" size="0.02 0.12" pos="0.05 0.02 -0.035" quat="0.707105 0 0.707108 0" type="cylinder" rgba="0.75294 0.75294 0.75294 1"/>
                  <geom name="r_foot_2" size="0.02 0.12" pos="0.05 -0.02 -0.035" quat="0.707105 0 0.707108 0" type="cylinder" rgba="0.75294 0.75294 0.75294 1"/>
                  
                  <!-- <geom name="r_foot_1" size="0.001 0.04 0.02" pos="-0.05 0.0 -0.035" type="box" rgba="0.75294 0.75294 0.75294 1"/>
                  <geom name="r_foot_2" size="0.001 0.04 0.02" pos="0.15 0.0 -0.035" type="box" rgba="0.75294 0.75294 0.75294 1"/> -->

                </body>
              </body>
            </body>
          </body>
        </body>
      </body>
    </body>
  </worldbody>

  <actuator>
    <!-- User parameter is the maximum no-load motor RPM -->
    <motor name="l_hip_roll" joint="l_hip_roll" ctrlrange="-48 48" user="116"/>
    <motor name="l_hip_yaw" joint="l_hip_yaw" ctrlrange="-66 66" user="160"/>
    <motor name="l_hip_pitch" joint="l_hip_pitch" ctrlrange="-225 225" user="357"/>
    <motor name="l_knee_pitch" joint="l_knee_pitch" ctrlrange="-225 225" user="357"/>
    <motor name="l_ankle_pitch" joint="l_ankle_pitch" ctrlrange="-15 15" user="194"/>
    <motor name="l_ankle_roll" joint="l_ankle_roll" ctrlrange="-30 30" user="194"/>
    <motor name="r_hip_roll" joint="r_hip_roll" ctrlrange="-48 48" user="116"/>
    <motor name="r_hip_yaw" joint="r_hip_yaw" ctrlrange="-66 66" user="160"/>
    <motor name="r_hip_pitch" joint="r_hip_pitch" ctrlrange="-225 225" user="357"/>
    <motor name="r_knee_pitch" joint="r_knee_pitch" ctrlrange="-225 225" user="357"/>
    <motor name="r_ankle_pitch" joint="r_ankle_pitch" ctrlrange="-15 15" user="194"/>
    <motor name="r_ankle_roll" joint="r_ankle_roll" ctrlrange="-30 30" user="194"/>

<!-- 
    <motor name="waist_yaw" joint="waist_yaw" ctrlrange="-66 66" user="160"/>
    <motor name="waist_pitch" joint="waist_pitch" ctrlrange="-66 66" user="160"/>
    <motor name="waist_roll" joint="waist_roll" ctrlrange="-66 66" user="160"/>
    <motor name="head_yaw" joint="head_yaw" ctrlrange="-10.2 10.2" user="233"/>    
    <motor name="head_roll" joint="head_roll" ctrlrange="-3.95 3.95" user="267"/>
    <motor name="head_pitch" joint="head_pitch" ctrlrange="-3.95 3.95" user="267"/>
    <motor name="l_shoulder_pitch" joint="l_shoulder_pitch" ctrlrange="-38 38" user="87"/>
    <motor name="l_shoulder_roll" joint="l_shoulder_roll" ctrlrange="-38 38" user="87"/>
    <motor name="l_shoulder_yaw" joint="l_shoulder_yaw" ctrlrange="-30 30" user="70"/>
    <motor name="l_elbow_pitch" joint="l_elbow_pitch" ctrlrange="-30 30" user="70"/>
    <motor name="l_wrist_yaw" joint="l_wrist_yaw" ctrlrange="-10.2 10.2" user="233"/>
    <motor name="l_wrist_roll" joint="l_wrist_roll" ctrlrange="-3.95 3.95" user="267"/>
    <motor name="l_wrist_pitch" joint="l_wrist_pitch" ctrlrange="-3.95 3.95" user="267"/>
    <motor name="r_shoulder_pitch" joint="r_shoulder_pitch" ctrlrange="-38 38" user="87"/>
    <motor name="r_shoulder_roll" joint="r_shoulder_roll" ctrlrange="-38 38" user="87"/>
    <motor name="r_shoulder_yaw" joint="r_shoulder_yaw" ctrlrange="-30 30" user="70"/>
    <motor name="r_elbow_pitch" joint="r_elbow_pitch" ctrlrange="-30 30" user="70"/>
    <motor name="r_wrist_yaw" joint="r_wrist_yaw" ctrlrange="-10.2 10.2" user="233"/>
    <motor name="r_wrist_roll" joint="r_wrist_roll" ctrlrange="-3.95 3.95" user="267"/>
    <motor name="r_wrist_pitch" joint="r_wrist_pitch" ctrlrange="-3.95 3.95" user="267"/> -->
  </actuator>

  <sensor>
    <accelerometer name="accel" site="imu"/>
    <gyro name="gyro" site="imu"/>
    <jointpos name="l_hip_roll_pos" joint="l_hip_roll"/>
    <jointpos name="l_hip_yaw_pos" joint="l_hip_yaw"/>
    <jointpos name="l_hip_pitch_pos" joint="l_hip_pitch"/>
    <jointpos name="l_knee_pitch_pos" joint="l_knee_pitch"/>
    <jointpos name="l_ankle_pitch_pos" joint="l_ankle_pitch"/>
    <jointpos name="l_ankle_roll_pos" joint="l_ankle_roll"/>
    <jointpos name="r_hip_roll_pos" joint="r_hip_roll"/>
    <jointpos name="r_hip_yaw_pos" joint="r_hip_yaw"/>
    <jointpos name="r_hip_pitch_pos" joint="r_hip_pitch"/>
    <jointpos name="r_knee_pitch_pos" joint="r_knee_pitch"/>
    <jointpos name="r_ankle_pitch_pos" joint="r_ankle_pitch"/>
    <jointpos name="r_ankle_roll_pos" joint="r_ankle_roll"/>
    <jointvel name="l_hip_roll_vel" joint="l_hip_roll"/>
    <jointvel name="l_hip_yaw_vel" joint="l_hip_yaw"/>
    <jointvel name="l_hip_pitch_vel" joint="l_hip_pitch"/>
    <jointvel name="l_knee_pitch_vel" joint="l_knee_pitch"/>
    <jointvel name="l_ankle_pitch_vel" joint="l_ankle_pitch"/>
    <jointvel name="l_ankle_roll_vel" joint="l_ankle_roll"/>
    <jointvel name="r_hip_roll_vel" joint="r_hip_roll"/>
    <jointvel name="r_hip_yaw_vel" joint="r_hip_yaw"/>
    <jointvel name="r_hip_pitch_vel" joint="r_hip_pitch"/>
    <jointvel name="r_knee_pitch_vel" joint="r_knee_pitch"/>
    <jointvel name="r_ankle_pitch_vel" joint="r_ankle_pitch"/>
    <jointvel name="r_ankle_roll_vel" joint="r_ankle_roll"/>
    <!-- <velocimeter name="BodyVel" site="imu"/> -->
    <!-- <framepos name="BodyPos" objtype="site" objname="imu"/>
    <framequat name="BodyQuat" objtype="site" objname="imu"/> -->
  </sensor>

</mujoco>
