<?xml version="1.0" encoding="utf-8"?>
<!-- This URDF was automatically created by SolidWorks to URDF Exporter! Originally created by Stephen Brawner (brawner@gmail.com) 
     Commit Version: 1.6.0-4-g7f85cfe  Build Version: 1.6.7995.38578
     For more information, please see http://wiki.ros.org/sw_urdf_exporter -->
<robot
  name="pai_12dof_v2_0312">

<!-- 
  <link name="world" />
  <joint name ="weld" type="revolute">
    <parent link="world"/>
    <child link="base_link"/>
    <origin xyz="0 0 0"/>
    <joint xyz="0 0 1"/>
  </joint> -->

  <link
    name="base_link">
    <inertial>
      <origin xyz="-0.048532 -0.00089322 -0.032851" rpy="0 0 0" />
      <mass value="4.9859" />
      <inertia ixx="0.045749" ixy="-0.00020848" ixz="-0.0025121" iyy="0.016772" iyz="-4.364E-05"
        izz="0.048814" />
    </inertial>
    
    <collision>
      <origin
        xyz="0.04 0 0.06"
        rpy="0 0 0" />
			<geometry>
				<box size="0.2 0.2 0.12" />
			</geometry>
    </collision>
  </link>


  <joint name="imu_joint" type="fixed">
      <origin rpy="0. 0. 0." xyz="0. 0. 0"/>
      <parent link="base_link"/>
      <child link="imu_link"/>
    </joint>
    <!-- Imu link -->
    <link name="imu_link">
      <inertial>
        <mass value="0.01"/>
        <origin rpy="0 0 0" xyz="0 0 0"/>
        <inertia ixx="0.000001" ixy="0" ixz="0" iyy="0.000001" iyz="0" izz="0.000001"/>
      </inertial>
      
      <material name="orange">
        <color rgba="255 108 10 255"/>
      </material>
    </link>

  <!-- ************************************************************ -->
  <!-- ************************ Left Leg ************************** -->
  <!-- ************************************************************ -->
  
  <!-- ************* part 2 *************** -->
  <joint
    name="l_hip_roll"
    type="revolute">
    <origin xyz="-0.0480000000000005 0.105 -0.0575" rpy="0 0 0" />
    <parent
      link="base_link" />
    <child
      link="leg_l2_link" />
    <axis xyz="1 0 0" />
    <limit lower="-0.09" upper="0.79" effort="48" velocity="12.15" />
  </joint>
  <link
    name="leg_l2_link">
    <inertial>
      <origin
        xyz="-0.0578492 0 -0.0416749"
        rpy="0 0 0" />
      <mass
        value="0.3887654" />
      <inertia
        ixx="0.0002521"
        ixy="0"
        ixz="-0.0001456"
        iyy="0.0004324"
        iyz="0"
        izz="0.0003133" />
    </inertial>
    
    <collision>
			<origin xyz="0 0 0" rpy="0 0 0" />
			<geometry>
				<box size="0.0001 0.0001 0.0001" />
			</geometry>
    </collision>
  </link>
  
	<!-- ************* part 1 *************** -->
  <joint
    name="l_hip_yaw"
    type="revolute">
<origin xyz="0.048 0 -0.0304999999999989" rpy="0 0 0" />
    <parent
      link="leg_l2_link" />
    <child
      link="leg_l1_link" />
    <axis xyz="0 0 1" />
    <limit lower="-0.7" upper="0.7" effort="66" velocity="16.76" />

  </joint>
  <link
    name="leg_l1_link">
    <inertial>
      <origin
        xyz="0.0373373 -0.0004323 0.0004287"
        rpy="0 0 0" />
      <mass
        value="0.74952" />
      <inertia
        ixx="0.0013819"
        ixy="-1.6E-06"
        ixz="5.4E-06"
        iyy="0.0003384"
        iyz="2E-07"
        izz="0.0014434" />
    </inertial>
    
    <collision>
			<origin rpy="0 0 0" xyz="0 0 0" />
			<geometry>
				<box size="0.0001 0.0001 0.0001" />
			</geometry>
    </collision>
  </link>
  

	<!-- ************* part 3 *************** -->
  <joint
    name="l_hip_pitch"
    type="revolute">
    <origin xyz="0 0 -0.109999999999336" rpy="0 0 0" />
    <parent
      link="leg_l1_link" />
    <child
      link="leg_l3_link" />
    <axis xyz="0 1 0" />
    <limit lower="-1.75" upper="0.7" effort="225" velocity="37.38" />

  </joint>
  <link
    name="leg_l3_link">
    <inertial>
      <origin
        xyz="0.004364 0.0013366 -0.046554"
        rpy="0 0 0" />
      <mass
        value="0.1443603" />
      <inertia
        ixx="0.0004365"
        ixy="8E-07"
        ixz="3.66E-05"
        iyy="0.0004422"
        iyz="-9E-06"
        izz="4.91E-05" />
    </inertial>
    
    <collision>
			<origin xyz="0.00 0 -0.05" rpy="0 0 0" />
            <geometry>
                <box size="0.01 0.01 0.09" />
            </geometry>
    </collision>
  </link>
  

	<!-- ************* part 4 *************** -->
  <joint
    name="l_knee_pitch"
    type="revolute">
    <origin xyz="0 0 -0.359995124115987" rpy="0 0 0" />
    <parent
      link="leg_l3_link" />
    <child
      link="leg_l4_link" />
    <axis xyz="0 1 0" />
    <limit lower="-0.09" upper="1.92" effort="225" velocity="37.38" />

  </joint>
  <link
    name="leg_l4_link">
    <inertial>
      <origin
        xyz="0.0035389 0 -0.07142"
        rpy="0 0 0" />
      <mass
        value="0.768122" />
      <inertia
        ixx="0.0010371"
        ixy="0"
        ixz="-9.4E-06"
        iyy="0.0010674"
        iyz="-3.3E-06"
        izz="0.0002151" />
    </inertial>
    
    <collision>
			<origin xyz="0.0 0.0 -0.05" rpy="0 0 0" />
			<geometry>
				<box size="0.01 0.01 0.09" />
			</geometry>
    </collision>
  </link>
  

	<!-- ************* part 5 *************** -->
  <joint
    name="l_ankle_pitch"
    type="revolute">
    <origin xyz="0 0 -0.339999992262544" rpy="0 0 0" />
    <parent
      link="leg_l4_link" />
    <child
      link="leg_l5_link" />
    <axis xyz="0 1 0" />
    <limit lower="-1.05" upper="0.52" effort="15" velocity="20.32" />
  </joint>
  <link
    name="leg_l5_link">
    <inertial>
      <origin
        xyz="0 0 0"
        rpy="0 0 0" />
      <mass
        value="0.0088647" />
      <inertia
        ixx="2E-07"
        ixy="0"
        ixz="0"
        iyy="1E-06"
        iyz="0"
        izz="1E-06" />
    </inertial>
    
    <!-- <collision>
			<origin xyz="0.012 0.0 0.0" rpy="0 0 0" />
      <geometry>
        <box size="0.00 0.00 0.00" />
      </geometry>
    </collision> -->
  </link>
  
  <link
    name="l_ankle_roll_link">
    <inertial>
      <origin
        xyz="0.0240775 0 -0.018709"
        rpy="0 0 0" />
      <mass
        value="0.1728932" />
      <inertia
        ixx="7.78E-05"
        ixy="0"
        ixz="2.11E-05"
        iyy="0.0003287"
        iyz="0"
        izz="0.0003779" />
    </inertial>
    
    <collision>
      <origin
        xyz="0.035 0 -0.025"
        rpy="0 0 0" />
      <geometry>
				<box size="0.14 0.07 0.015" />
			</geometry>
    </collision>
  </link>
  <joint
    name="l_ankle_roll"
    type="revolute">
    <origin
      xyz="0 0 0"
      rpy="0 0 0" />
    <parent
      link="leg_l5_link" />
    <child
      link="l_ankle_roll_link" />
    <axis
      xyz="1 0 0" />
    <limit lower="-0.44" upper="0.44" effort="30" velocity="20.32" />
  </joint>

 <joint name="leg_l5_fixed_1" type="fixed">
    <origin xyz="0.1 0 -0.0100" rpy="0 0 0" />
    <parent link="l_ankle_roll_link" />
    <child link="l_foot_toe" />
  </joint>
  <link name="l_foot_toe">
    <inertial>
      <mass value="0.01" />
      <inertia ixx="0.000001" ixy="0" ixz="0" iyy="0.000001" iyz="0" izz="0.000001" />
    </inertial>
    
    <collision>
      <origin rpy="0 0 0" xyz="0 0 0"/>
      <geometry>
        <sphere radius="0.001"/>
      </geometry>
    </collision>
  </link>

  <joint name="leg_l5_fixed_2" type="fixed">
    <origin xyz="-0.04 0 -0.0100" rpy="0 0 0" />
    <parent link="l_ankle_roll_link" />
    <child link="l_foot_heel" />
  </joint>
  <link name="l_foot_heel">
    <inertial>
      <mass value="0.01" />
      <inertia ixx="0.000001" ixy="0" ixz="0" iyy="0.000001" iyz="0" izz="0.000001" />
    </inertial>
    
    <collision>
      <origin rpy="0 0 0" xyz="-0 0 0"/>
      <geometry>
        <sphere radius="0.001"/>
      </geometry>
    </collision>
  </link>

  <!-- ************************************************************ -->
  <!-- ************************ Right Leg ************************** -->
  <!-- ************************************************************ -->
	

  <!-- ************* part 2 *************** -->
  <joint
    name="r_hip_roll"
    type="revolute">
    <origin xyz="-0.0480000000000003 -0.105 -0.0575" rpy="0 0 0" />
    <parent
      link="base_link" />
    <child
      link="leg_r2_link" />
<axis xyz="1 0 0" />
    <limit lower="-0.79" upper="0.09" effort="48" velocity="12.15" />

  </joint>
  <link
    name="leg_r2_link">
    <inertial>
      <origin
        xyz="-0.0578492 0 -0.0416749"
        rpy="0 0 0" />
      <mass
        value="0.3887654" />
      <inertia
        ixx="0.0002521"
        ixy="0"
        ixz="-0.0001456"
        iyy="0.0004324"
        iyz="0"
        izz="0.0003133" />
    </inertial>
    
    <collision>
			<origin xyz="0 0 0" rpy="0 0 0" />
			<geometry>
				<box size="0.0001 0.0001 0.0001" />
			</geometry>
    </collision>
  </link>
  



  <!-- ************* part 1 *************** -->
  <joint
    name="r_hip_yaw"
    type="revolute">
    <origin xyz="0.0480000000000212 0 -0.0305000000000011" rpy="0 0 0" />

    <parent
      link="leg_r2_link" />
    <child
      link="leg_r1_link" />
    <axis xyz="0 0 1" />
    <limit lower="-0.7" upper="0.7" effort="66" velocity="16.76" />

  </joint>
  <link
    name="leg_r1_link">
    <inertial>
      <origin
        xyz="0.0373373 0.0004272 0.0004287"
        rpy="0 0 0" />
      <mass
        value="0.7495221" />
      <inertia
        ixx="0.0013819"
        ixy="-3E-06"
        ixz="5.4E-06"
        iyy="0.0003384"
        iyz="6E-07"
        izz="0.0014434" />
    </inertial>
    
    <collision>
      <origin
        xyz="0 0 0"
        rpy="0 0 0" />
			<geometry>
				<box size="0.0001 0.0001 0.0001" />
			</geometry>
    </collision>
  </link>
  

  <!-- ************* part 3 *************** -->

<joint
    name="r_hip_pitch"
    type="revolute">
    <origin xyz="0 0 -0.109999999999337" rpy="0 0 0" />
    <parent
      link="leg_r1_link" />
    <child
      link="leg_r3_link" />
    <axis xyz="0 1 0" />
    <limit lower="-1.75" upper="0.7" effort="225" velocity="37.38" />
  </joint>
  <link
    name="leg_r3_link">
    <inertial>
      <origin
        xyz="0.004364 -0.0013366 -0.0465535"
        rpy="0 0 0" />
      <mass
        value="0.1443603" />
      <inertia
        ixx="0.0004365"
        ixy="-8E-07"
        ixz="3.66E-05"
        iyy="0.0004422"
        iyz="9E-06"
        izz="4.91E-05" />
    </inertial>
    
    <collision>
			<origin xyz="0.0 0 -0.05" rpy="0 0 0" />
			<geometry>
				<box size="0.01 0.01 0.09" />
			</geometry>
    </collision>
  </link>
  


  <!-- ************* part 4 *************** -->
<joint
    name="r_knee_pitch"
    type="revolute">
    <origin xyz="0 0 -0.359995124115985" rpy="0 0 0" />
    <parent
      link="leg_r3_link" />
    <child
      link="leg_r4_link" />
    <axis xyz="0 1 0" />
    <limit lower="-0.09" upper="1.92" effort="225" velocity="37.38" />
  </joint>

  <link
    name="leg_r4_link">
    <inertial>
      <origin
        xyz="0.0035389 0 -0.0714471"
        rpy="0 0 0" />
      <mass
        value="0.768122" />
      <inertia
        ixx="0.0010371"
        ixy="0"
        ixz="-9.4E-06"
        iyy="0.0010674"
        iyz="-3.3E-06"
        izz="0.0002151" />
    </inertial>
    
    <collision>
			<origin xyz="0.00 0.0 -0.05" rpy="0 0 0" />
			<geometry>
				<box size="0.01 0.01 0.09" />
			</geometry>
    </collision>
  </link>
  

  <!-- ************* part 5 *************** -->
  <joint
    name="r_ankle_pitch"
    type="revolute">
    <origin xyz="0 0 -0.339999999788054" rpy="0 0 0" />
    <parent
      link="leg_r4_link" />
    <child
      link="leg_r5_link" />
    <axis xyz="0 1 0" />
    <limit lower="-1.05" upper="0.52" effort="15" velocity="20.32" />
  </joint>
  <link
    name="leg_r5_link">
    <inertial>
      <origin
        xyz="0 0 0"
        rpy="0 0 0" />
      <mass
        value="0.0088647" />
      <inertia
        ixx="2E-07"
        ixy="0"
        ixz="0"
        iyy="1E-06"
        iyz="0"
        izz="1E-06" />
    </inertial>
    
    <!-- <collision>
			<origin xyz="0.012 0.0 0.0" rpy="0 0 0" />
			<geometry>
				<box size="0.0 0.0 0.0" />
			</geometry>
    </collision> -->
  </link>
  
  <link
    name="r_ankle_roll_link">
    <inertial>
      <origin
        xyz="0.0240775 0 -0.018709"
        rpy="0 0 0" />
      <mass
        value="0.1728932" />
      <inertia
        ixx="7.78E-05"
        ixy="0"
        ixz="2.11E-05"
        iyy="0.0003287"
        iyz="0"
        izz="0.0003779" />
    </inertial>
    
    <collision>
      <origin
        xyz="0.035 0 -0.025"
        rpy="0 0 0" />
      <geometry>
				<box size="0.14 0.07 0.015" />
			</geometry>
    </collision>
  </link>
  <joint
    name="r_ankle_roll"
    type="revolute">
    <origin
      xyz="0 0 0"
      rpy="0 0 0" />
    <parent
      link="leg_r5_link" />
    <child
      link="r_ankle_roll_link" />
    <axis
      xyz="1 0 0" />
    <limit
      lower="-1.2"
      upper="1.2"
      effort="21"
      velocity="21" />
  </joint>


  <joint name="leg_r5_fixed_1" type="fixed">
    <origin xyz="0.1 0 -0.0100" rpy="0 0 0" />
    <parent link="r_ankle_roll_link" />
    <child link="r_foot_toe" />
  </joint>
  <link name="r_foot_toe">
    <inertial>
      <mass value="0.01" />
      <inertia ixx="0.000001" ixy="0" ixz="0" iyy="0.000001" iyz="0" izz="0.000001" />
    </inertial>
    
    <collision>
      <origin rpy="0 0 0" xyz="0 0 0"/>
      <geometry>
        <sphere radius="0.001"/>
      </geometry>
    </collision>
  </link>

  <joint name="leg_r5_fixed_2" type="fixed">
    <origin xyz="-0.040 0 -0.0100" rpy="0 0 0" />
    <parent link="r_ankle_roll_link" />
    <child link="r_foot_heel" />
  </joint>
  <link name="r_foot_heel">
    <inertial>
      <mass value="0.01" />
      <inertia ixx="0.000001" ixy="0" ixz="0" iyy="0.000001" iyz="0" izz="0.000001" />
    </inertial>
    
    <collision>
      <origin rpy="0 0 0" xyz="0 0 0"/>
      <geometry>
        <sphere radius="0.001"/>
      </geometry>
    </collision>
  </link>






  <link name="link_waist_yaw">
    <inertial>
      <origin xyz="-0.0049526 -0.00090609 0.0262" rpy="0 0 0" />
      <mass value="0.50743792" />
      <inertia ixx="0.00110565" ixy="-4.9E-07" ixz="4.837E-05" iyy="0.00082433" iyz="1.198E-05"
        izz="0.00141909" />
    </inertial>
    
  </link>
  <joint name="joint_waist_yaw" type="revolute">
    <origin xyz="0 0 0.00649999999999984" rpy="0 0 0" />
    <parent link="base_link" />
    <child link="link_waist_yaw" />
    <axis xyz="0 0 1" />
    <limit lower="-1.05" upper="1.05" effort="66" velocity="16.76" />
  </joint>
  <link name="link_waist_pitch">
    <inertial>
      <origin xyz="0.0045612 -0.0044005 0.040369" rpy="0 0 0" />
      <mass value="2.90421452" />
      <inertia ixx="0.00845426" ixy="-5.355E-05" ixz="-0.00049265" iyy="0.00844076"
        iyz="-0.00047579" izz="0.00329151" />
    </inertial>
    
  </link>
  <joint name="joint_waist_pitch" type="revolute">
    <origin xyz="0 0 0.0570000000000001" rpy="0 0 0" />
    <parent link="link_waist_yaw" />
    <child link="link_waist_pitch" />
    <axis xyz="0 1 0" />
    <limit lower="-0.52" upper="1.22" effort="66" velocity="16.76" />
  </joint>
  <link name="link_waist_roll">
    <inertial>
      <origin xyz="-0.0094995 8.7428E-05 0.16729" rpy="0 0 0" />
      <mass value="7.54469333" />
      <inertia ixx="0.06293498" ixy="5.308E-05" ixz="0.00175668" iyy="0.05101438" iyz="-3.98E-06"
        izz="0.03853047" />
    </inertial>
    
    <collision>
      <origin xyz="0 0 0.15" rpy="0 0 0" />
      <geometry>
        <cylinder length="0.2" radius="0.1" />
      </geometry>
    </collision>
  </link>
  <joint name="joint_waist_roll" type="revolute">
    <origin xyz="0 0 0.081" rpy="0 0 0" />
    <parent link="link_waist_pitch" />
    <child link="link_waist_roll" />
    <axis xyz="1 0 0" />
    <limit lower="-0.7" upper="0.7" effort="66" velocity="16.76" />
  </joint>
  <link name="link_torso">
    <inertial>
      <origin xyz="0 0 0" rpy="0 0 0" />
      <mass value="0.0" />
      <inertia ixx="0.0" ixy="0.0" ixz="0.0" iyy="0.0" iyz="0.0" izz="0.0" />
    </inertial>
  </link>
  <joint name="joint_torso" type="fixed">
    <origin xyz="0 0 0.160213351037685" rpy="0 0 0" />
    <parent link="link_waist_roll" />
    <child link="link_torso" />
    <axis xyz="0 0 0" />
  </joint>
  <link name="l_upper_arm_pitch">
    <inertial>
      <origin xyz="0.0054188 0.05902 0.00011843" rpy="0 0 0" />
      <mass value="0.78809" />
      <inertia ixx="0.0007753" ixy="-2.589E-05" ixz="3.7E-07" iyy="0.00049478" iyz="7.2E-06"
        izz="0.00067965" />
    </inertial>
    
  </link>
  <joint name="l_shoulder_pitch" type="revolute">
    <origin xyz="0 0.126623540943386 0.0590455268445764" rpy="0.436334785573203 0 0" />
    <parent link="link_torso" />
    <child link="l_upper_arm_pitch" />
    <axis xyz="0 1 0" />
    <limit lower="-2.79" upper="1.92" effort="38" velocity="9.11" />
  </joint>
  <link name="l_upper_arm_roll">
    <inertial>
      <origin xyz="0.01986 0.02608 -0.025535" rpy="0 0 0" />
      <mass value="0.1786" />
      <inertia ixx="0.000202" ixy="3.959E-05" ixz="-4.406E-05" iyy="0.00016117" iyz="4.295E-05"
        izz="0.00017433" />
    </inertial>
    
    <collision>
      <origin xyz="0 0 0" rpy="0 0 0" />
      <geometry>
        <sphere radius="0.04" />
      </geometry>

    </collision>
  </link>
  <joint name="l_shoulder_roll" type="revolute">
    <origin xyz="0 0.0669999999997965 0" rpy="-0.436334785573203 0 0" />
    <parent link="l_upper_arm_pitch" />
    <child link="l_upper_arm_roll" />
    <axis xyz="1 0 0" />
    <limit lower="-0.57" upper="3.27" effort="38" velocity="9.11" />
  </joint>
  <link name="l_upper_arm_yaw">
    <inertial>
      <origin xyz="0.00010029 0.0012809 -0.097194" rpy="0 0 0" />
      <mass value="0.98085" />
      <inertia ixx="0.00618618" ixy="-1.2E-07" ixz="1.28E-06" iyy="0.00611274" iyz="0.00019627"
        izz="0.00057714" />
    </inertial>
    
    <collision>
      <origin xyz="0 0 -0.05" rpy="0 0 0" />
      <geometry>
        <cylinder length="0.11" radius="0.03" />
      </geometry>

    </collision>
  </link>
  <joint name="l_shoulder_yaw" type="revolute">
    <origin xyz="0 0.040381430445538 -0.0572327709897897" rpy="0 0 0" />
    <parent link="l_upper_arm_roll" />
    <child link="l_upper_arm_yaw" />
    <axis xyz="0 0 1" />
    <limit lower="-2.97" upper="2.97" effort="30" velocity="7.33" />
  </joint>
  <link name="l_lower_arm_pitch">
    <inertial>
      <origin xyz="7.6884E-09 0.020584 -0.020113" rpy="0 0 0" />
      <mass value="0.059535" />
      <inertia ixx="2.796E-05" ixy="0" ixz="0" iyy="2.596E-05" iyz="-7.95E-06" izz="1.931E-05" />
    </inertial>
    
  </link>
  <joint name="l_elbow_pitch" type="revolute">
    <origin xyz="0 0.00125501157055688 -0.188749174791823" rpy="0 0 0" />
    <parent link="l_upper_arm_yaw" />
    <child link="l_lower_arm_pitch" />
    <axis xyz="0 1 0" />
    <limit lower="-2.27" upper="2.27" effort="30" velocity="7.33" />
  </joint>
  <link name="l_hand_yaw">
    <inertial>
      <origin xyz="-0.00048885 0.0013916 -0.08204" rpy="0 0 0" />
      <mass value="1.2684" />
      <inertia ixx="0.00419457" ixy="6.15E-06" ixz="5E-07" iyy="0.00409118" iyz="-1.263E-05"
        izz="0.00084731" />
    </inertial>
    
    <collision>
      <origin xyz="0 0 -0.08" rpy="0 0 0" />
      <geometry>
        <cylinder length="0.17" radius="0.035" />
      </geometry>
    </collision>
  </link>
  <joint name="l_wrist_yaw" type="revolute">
    <origin xyz="0 0.000299612107771352 -0.0404989031042769" rpy="0 0 0" />
    <parent link="l_lower_arm_pitch" />
    <child link="l_hand_yaw" />
    <axis xyz="0 0 1" />
    <limit lower="-2.97" upper="2.97" effort="10.2" velocity="24.4" />
  </joint>
  <link name="l_hand_roll">
    <inertial>
      <origin xyz="1.566E-08 -0.00043791 -2.922E-06" rpy="0 0 0" />
      <mass value="0.0054351" />
      <inertia ixx="7E-08" ixy="0" ixz="0" iyy="3.6E-07" iyz="0" izz="3.6E-07" />
    </inertial>
    
  </link>
  <joint name="l_wrist_roll" type="revolute">
    <origin xyz="0 0.00133699944291396 -0.20107985186864" rpy="0 0 0" />
    <parent link="l_hand_yaw" />
    <child link="l_hand_roll" />
    <axis xyz="1 0 0" />
    <limit lower="-0.96" upper="0.87" effort="3.95" velocity="27.96" />
  </joint>
  <link name="l_hand_pitch">
    <inertial>
      <origin xyz="0.0058876 -0.0010755 -0.082238" rpy="0 0 0" />
      <mass value="0.54891" />
      <inertia ixx="0.0011317" ixy="0.00013711" ixz="-2.516E-05" iyy="0.0014781" iyz="4.232E-05"
        izz="0.00058665" />
    </inertial>
    
    <collision>
      <origin xyz="0 0 -0.07" rpy="0 0 0" />
      <geometry>
        <sphere radius="0.036" />
      </geometry>
    </collision>
  </link>
  <joint name="l_wrist_pitch" type="revolute">
    <origin xyz="0 0 0" rpy="0 0 0" />
    <parent link="l_hand_roll" />
    <child link="l_hand_pitch" />
    <axis xyz="0 1 0" />
    <limit lower="-0.61" upper="0.61" effort="3.95" velocity="27.96" />
  </joint>
  <link name="r_upper_arm_pitch">
    <inertial>
      <origin xyz="0.0054189 -0.058978 0.0001189" rpy="0 0 0" />
      <mass value="0.78809" />
      <inertia ixx="0.00077478" ixy="2.506E-05" ixz="3.6E-07" iyy="0.00049477" iyz="-9.49E-06"
        izz="0.00067913" />
    </inertial>
    
  </link>
  <joint name="r_shoulder_pitch" type="revolute">
    <origin xyz="0 -0.126623540926852 0.0590455268368039" rpy="-0.436332306093773 0 0" />
    <parent link="link_torso" />
    <child link="r_upper_arm_pitch" />
    <axis xyz="0 1 0" />
    <limit lower="-2.79" upper="1.92" effort="38" velocity="9.11" />
  </joint>
  <link name="r_upper_arm_roll">
    <inertial>
      <origin xyz="0.019868 -0.025881 -0.025684" rpy="0 0 0" />
      <mass value="0.1786" />
      <inertia ixx="0.00020199" ixy="-3.928E-05" ixz="-4.432E-05" iyy="0.00016173" iyz="-4.302E-05"
        izz="0.00017374" />
    </inertial>
    
    <collision>
      <origin xyz="0 0 0" rpy="0 0 0" />
      <geometry>
        <sphere radius="0.04" />
      </geometry>
    </collision>
  </link>
  <joint name="r_shoulder_roll" type="revolute">
    <origin xyz="0 -0.0670000000000026 0" rpy="0.436332306093773 0 0" />
    <parent link="r_upper_arm_pitch" />
    <child link="r_upper_arm_roll" />
    <axis xyz="1 0 0" />
    <limit lower="-3.27" upper="0.57" effort="38" velocity="9.11" />
  </joint>
  <link name="r_upper_arm_yaw">
    <inertial>
      <origin xyz="-0.00010032 -0.00063501 -0.097127" rpy="0 0 0" />
      <mass value="0.98085" />
      <inertia ixx="0.0061732" ixy="1E-08" ixz="-1.2E-06" iyy="0.00610224" iyz="-0.00015934"
        izz="0.00057482" />
    </inertial>
    
    <collision>
      <origin xyz="0 0 -0.05" rpy="0 0 0" />
      <geometry>
        <cylinder length="0.11" radius="0.03" />
      </geometry>
    </collision>
  </link>
  <joint name="r_shoulder_yaw" type="revolute">
    <origin xyz="0 -0.039999999998954 -0.0575000000000302" rpy="0 0 0" />
    <parent link="r_upper_arm_roll" />
    <child link="r_upper_arm_yaw" />
    <axis xyz="0 0 1" />
    <limit lower="-2.97" upper="2.97" effort="30" velocity="7.33" />
  </joint>
  <link name="r_lower_arm_pitch">
    <inertial>
      <origin xyz="-7.6455E-09 -0.020449 -0.020249" rpy="0 0 0" />
      <mass value="0.059535" />
      <inertia ixx="2.796E-05" ixy="0" ixz="0" iyy="2.586E-05" iyz="8E-06" izz="1.942E-05" />
    </inertial>
    
  </link>
  <joint name="r_elbow_pitch" type="revolute">
    <origin xyz="0 0 -0.188530330300762" rpy="0 0 0" />
    <parent link="r_upper_arm_yaw" />
    <child link="r_lower_arm_pitch" />
    <axis xyz="0 1 0" />
    <limit lower="-2.27" upper="2.27" effort="30" velocity="7.33" />
  </joint>
  <link name="r_hand_yaw">
    <inertial>
      <origin xyz="0.00048881 -0.00084627 -0.082047" rpy="0 0 0" />
      <mass value="1.2684" />
      <inertia ixx="0.00419457" ixy="6.15E-06" ixz="-4.6E-07" iyy="0.00409087" iyz="3.42E-05"
        izz="0.00084762" />
    </inertial>
    
    <collision>
      <origin xyz="0 0 -0.08" rpy="0 0 0" />
      <geometry>
        <cylinder length="0.17" radius="0.035" />
      </geometry>
    </collision>
  </link>
  <joint name="r_wrist_yaw" type="revolute">
    <origin xyz="0 -3.03303104252084E-05 -0.0404999999922469" rpy="0 0 0" />
    <parent link="r_lower_arm_pitch" />
    <child link="r_hand_yaw" />
    <axis xyz="0 0 1" />
    <limit lower="-2.97" upper="2.97" effort="10.2" velocity="24.4" />
  </joint>
  <link name="r_hand_roll">
    <inertial>
      <origin xyz="-1.552E-08 0.00043792 -1.1275E-08" rpy="0 0 0" />
      <mass value="0.0054351" />
      <inertia ixx="7E-08" ixy="0" ixz="0" iyy="3.6E-07" iyz="0" izz="3.6E-07" />
    </inertial>
    
  </link>
  <joint name="r_wrist_roll" type="revolute">
    <origin xyz="0 0 -0.201084296746609" rpy="0 0 0" />
    <parent link="r_hand_yaw" />
    <child link="r_hand_roll" />
    <axis xyz="1 0 0" />
    <limit lower="-0.87" upper="0.96" effort="3.95" velocity="27.96" />
  </joint>
  <link name="r_hand_pitch">
    <inertial>
      <origin xyz="0.0058875 0.0016218 -0.082229" rpy="0 0 0" />
      <mass value="0.54891" />
      <inertia ixx="0.00113168" ixy="-0.00013694" ixz="-2.607E-05" iyy="0.00147867" iyz="-3.638E-05"
        izz="0.00058614" />
    </inertial>
    
    <collision>
      <origin xyz="0 0 -0.07" rpy="0 0 0" />
      <geometry>
        <sphere radius="0.036" />
      </geometry>
    </collision>
  </link>
  <joint name="r_wrist_pitch" type="revolute">
    <origin xyz="0 0 0" rpy="0 0 0" />
    <parent link="r_hand_roll" />
    <child link="r_hand_pitch" />
    <axis xyz="0 1 0" />
    <limit lower="-0.61" upper="0.61" effort="3.95" velocity="27.96" />
  </joint>
  <link name="link_head_pitch">
    <inertial>
      <origin xyz="0.00043792 1.5503E-08 -1.1298E-08" rpy="0 0 0" />
      <mass value="0.00543512" />
      <inertia ixx="3.6E-07" ixy="0" ixz="0" iyy="7E-08" iyz="0" izz="3.6E-07" />
    </inertial>
    
    <collision>
      <origin xyz="0 0 0.1" rpy="0 0 0" />
      <geometry>
        <sphere radius="0.07" />
      </geometry>
    </collision>
  </link>
  <joint name="joint_head_pitch" type="revolute">
    <origin xyz="0.000999999999997045 -0.000225512658326668 0.144786985472057" rpy="0 0 0" />
    <parent link="link_torso" />
    <child link="link_head_pitch" />
    <axis xyz="0 1 0" />
    <limit lower="-0.87" upper="0.87" effort="3.95" velocity="27.96" />
  </joint>
  <link name="link_head_roll">
    <inertial>
      <origin xyz="-0.003976 2.2544E-05 0.015347" rpy="0 0 0" />
      <mass value="0.07131711" />
      <inertia ixx="2.863E-05" ixy="0" ixz="-2.8E-06" iyy="2.039E-05" iyz="0" izz="2.713E-05" />
    </inertial>
    
  </link>
  <joint name="joint_head_roll" type="revolute">
    <origin xyz="0 0 0" rpy="0 0 0" />
    <parent link="link_head_pitch" />
    <child link="link_head_roll" />
    <axis xyz="1 0 0" />
    <limit lower="-0.35" upper="0.35" effort="3.95" velocity="27.96" />
  </joint>
  <link name="link_head_yaw">
    <inertial>
      <origin xyz="0.02323 0.00026918 0.11024" rpy="0 0 0" />
      <mass value="1.3898352" />
      <inertia ixx="0.00803907" ixy="-9.9E-07" ixz="0.00082206" iyy="0.00988205" iyz="-1.27E-06"
        izz="0.00625075" />
    </inertial>
    
  </link>
  <joint name="joint_head_yaw" type="revolute">
    <origin xyz="0 5.37300128340204E-05 0.0359999599039489" rpy="0 0 0" />
    <parent link="link_head_roll" />
    <child link="link_head_yaw" />
    <axis xyz="0 0 1" />
    <limit lower="-2.71" upper="2.71" effort="3.95" velocity="27.96" />
  </joint>

</robot>