<mujoco model="pai_12dof_v2_0312">
  <compiler angle="radian" meshdir="../meshes/"/>
  <default>
    <joint damping="0" armature="0.1"/>
  </default>
  <asset>
    <mesh name="base_link" file="base_link.STL"/>
    <mesh name="r_hip_yaw_link" file="r_hip_yaw_link.STL"/>
    <mesh name="r_hip_roll_link" file="r_hip_roll_link.STL"/>
    <mesh name="r_thigh_link" file="r_thigh_link.STL"/>
    <mesh name="r_calf_link" file="r_calf_link.STL"/>
    <mesh name="r_ankle_pitch_link" file="r_ankle_pitch_link.STL"/>
    <mesh name="r_ankle_roll_link" file="r_ankle_roll_link.STL"/>
    <mesh name="l_hip_yaw_link" file="l_hip_yaw_link.STL"/>
    <mesh name="l_hip_roll_link" file="l_hip_roll_link.STL"/>
    <mesh name="l_thigh_link" file="l_thigh_link.STL"/>
    <mesh name="l_calf_link" file="l_calf_link.STL"/>
    <mesh name="l_ankle_pitch_link" file="l_ankle_pitch_link.STL"/>
    <mesh name="l_ankle_roll_link" file="l_ankle_roll_link.STL"/>
  </asset>
  <worldbody>
    <body name="base_link">
      <!-- <inertial pos="0.0361335 -1.93631e-05 0.0234309" quat="0.533077 0.534953 -0.462539 0.464448" mass="1.42408" diaginertia="0.00797374 0.00516546 0.00418916"/> -->
      <inertial pos="-0.0485352 -0.000893041 -0.0328649" quat="0.358994 0.355193 -0.612215 0.608403" mass="4.9869" diaginertia="0.0502276 0.0443441 0.0167764"/>
      <freejoint/>
      <site name="imu" pos="0 0 0"/>
      <geom size="0.1 0.1 0.06" pos="0.04 0 0.06" type="box" rgba="0.75294 0.75294 0.75294 1"/>
      <body name="leg_l2_link" pos="-0.048 0.105 -0.0575">
        <inertial pos="-0.0578492 0 -0.0416749" quat="0.638398 0.304052 0.304052 0.638398" mass="0.388765" diaginertia="0.0004324 0.000431481 0.000133919"/>
        <joint name="l_hip_roll" pos="0 0 0" axis="1 0 0" range="-0.09 0.79"/>
        <geom size="5e-05 5e-05 5e-05" type="box" rgba="0.75294 0.75294 0.75294 1"/>
        <body name="leg_l1_link" pos="0.048 0 -0.0305">
          <inertial pos="0.0373373 -0.0004323 0.0004287" quat="0.521666 0.520835 -0.47816 0.47745" mass="0.74952" diaginertia="0.00144387 0.00138143 0.000338398"/>
          <joint name="l_hip_yaw" pos="0 0 0" axis="0 0 1" range="-0.7 0.7"/>
          <geom size="5e-05 5e-05 5e-05" type="box" rgba="0.75294 0.75294 0.75294 1"/>
          <body name="leg_l3_link" pos="0 0 -0.11">
            <inertial pos="0.004364 0.0013366 -0.046554" quat="0.700571 -0.0412528 -0.0246027 0.711964" mass="0.14436" diaginertia="0.000442407 0.000439927 4.54667e-05"/>
            <joint name="l_hip_pitch" pos="0 0 0" axis="0 1 0" range="-1.75 0.7"/>
            <geom size="0.005 0.005 0.045" pos="0 0 -0.05" type="box" rgba="0.75294 0.75294 0.75294 1"/>
            <body name="leg_l4_link" pos="0 0 -0.359995">
              <inertial pos="0.0035389 0 -0.07142" quat="0.707528 0.00267035 0.0054126 0.70666" mass="0.768122" diaginertia="0.00106741 0.00103721 0.00021498"/>
              <joint name="l_knee_pitch" pos="0 0 0" axis="0 1 0" range="-0.09 1.92"/>
              <geom size="0.005 0.005 0.045" pos="0 0 -0.05" type="box" rgba="0.75294 0.75294 0.75294 1"/>
              <body name="leg_l5_link" pos="0 0 -0.34">
                <inertial pos="0 0 0" quat="0.5 0.5 0.5 0.5" mass="0.0088647" diaginertia="1e-06 1e-06 2e-07"/>
                <joint name="l_ankle_pitch" pos="0 0 0" axis="0 1 0" range="-1.05 0.52"/>
                <body name="l_ankle_roll_link">
                  <inertial pos="0.0246916 0 -0.017806" quat="0 0.724768 0 0.688993" mass="0.192893" diaginertia="0.000479551 0.000430688 8.01379e-05"/>
                  <joint name="l_ankle_roll" pos="0 0 0" axis="1 0 0" range="-0.44 0.44"/>
                  <geom size="0.07 0.035 0.0075" pos="0.035 0 -0.035" type="box" rgba="0.75294 0.75294 0.75294 1"/>
                </body>
              </body>
            </body>
          </body>
        </body>
      </body>
      <body name="leg_r2_link" pos="-0.048 -0.105 -0.0575">
        <inertial pos="-0.0578492 0 -0.0416749" quat="0.638398 0.304052 0.304052 0.638398" mass="0.388765" diaginertia="0.0004324 0.000431481 0.000133919"/>
        <joint name="r_hip_roll" pos="0 0 0" axis="1 0 0" range="-0.79 0.09"/>
        <geom size="5e-05 5e-05 5e-05" type="box" rgba="0.75294 0.75294 0.75294 1"/>
        <body name="leg_r1_link" pos="0.048 0 -0.0305">
          <inertial pos="0.0373373 0.0004272 0.0004287" quat="0.522079 0.520414 -0.478425 0.477192" mass="0.749522" diaginertia="0.00144387 0.00138144 0.000338391"/>
          <joint name="r_hip_yaw" pos="0 0 0" axis="0 0 1" range="-0.7 0.7"/>
          <geom size="5e-05 5e-05 5e-05" type="box" rgba="0.75294 0.75294 0.75294 1"/>
          <body name="leg_r3_link" pos="0 0 -0.11">
            <inertial pos="0.004364 -0.0013366 -0.0465535" quat="0.711964 -0.0246027 -0.0412528 0.700571" mass="0.14436" diaginertia="0.000442407 0.000439927 4.54667e-05"/>
            <joint name="r_hip_pitch" pos="0 0 0" axis="0 1 0" range="-1.75 0.7"/>
            <geom size="0.005 0.005 0.045" pos="0 0 -0.05" type="box" rgba="0.75294 0.75294 0.75294 1"/>
            <body name="leg_r4_link" pos="0 0 -0.359995">
              <inertial pos="0.0035389 0 -0.0714471" quat="0.707528 0.00267035 0.0054126 0.70666" mass="0.768122" diaginertia="0.00106741 0.00103721 0.00021498"/>
              <joint name="r_knee_pitch" pos="0 0 0" axis="0 1 0" range="-0.09 1.92"/>
              <geom size="0.005 0.005 0.045" pos="0 0 -0.05" type="box" rgba="0.75294 0.75294 0.75294 1"/>
              <body name="leg_r5_link" pos="0 0 -0.34">
                <inertial pos="0 0 0" quat="0.5 0.5 0.5 0.5" mass="0.0088647" diaginertia="1e-06 1e-06 2e-07"/>
                <joint name="r_ankle_pitch" pos="0 0 0" axis="0 1 0" range="-1.05 0.52"/>
                <body name="r_ankle_roll_link">
                  <inertial pos="0.0246916 0 -0.017806" quat="0 0.724768 0 0.688993" mass="0.192893" diaginertia="0.000479551 0.000430688 8.01379e-05"/>
                  <joint name="r_ankle_roll" pos="0 0 0" axis="1 0 0" range="-1.2 1.2"/>
                  <geom size="0.07 0.035 0.0075" pos="0.035 0 -0.035" type="box" rgba="0.75294 0.75294 0.75294 1"/>
                </body>
              </body>
            </body>
          </body>
        </body>
      </body>
      <body name="link_waist_yaw" pos="0 0 0.0065">
        <inertial pos="-0.0049526 -0.00090609 0.0262" quat="0.542631 0.529181 -0.457917 0.464576" mass="0.507438" diaginertia="0.00142661 0.00109837 0.000824081"/>
        <!-- <joint name="joint_waist_yaw" pos="0 0 0" axis="0 0 1" range="-1.05 1.05"/> -->
        
        <body name="link_waist_pitch" pos="0 0 0.057">
          <inertial pos="0.0045612 -0.0044005 0.040369" quat="0.978202 -0.0539856 0.0371241 -0.197049" mass="2.90421" diaginertia="0.00850445 0.00848089 0.00320118"/>
          <!-- <joint name="joint_waist_pitch" pos="0 0 0" axis="0 1 0" range="-0.52 1.22"/> -->
          
          <body name="link_waist_roll" pos="0 0 0.081">
            <inertial pos="-0.0094995 8.7428e-05 0.16729" quat="0.999359 -0.000385668 -0.0357383 0.00217327" mass="7.54469" diaginertia="0.063061 0.0510142 0.0384047"/>
            <!-- <joint name="joint_waist_roll" pos="0 0 0" axis="1 0 0" range="-0.7 0.7"/> -->
            
            <geom size="0.1 0.1" pos="0 0 0.15" type="cylinder" rgba="0.75294 0.75294 0.75294 1"/>
            <body name="l_upper_arm_pitch" pos="0 0.126624 0.219259" quat="0.976296 0.216441 0 0">
              <inertial pos="0.0054188 0.05902 0.00011843" quat="0.719753 0.692726 -0.0305981 -0.0339146" mass="0.78809" diaginertia="0.00077767 0.000679926 0.000492134"/>
              <!-- <joint name="l_shoulder_pitch" pos="0 0 0" axis="0 1 0" range="-2.79 1.92"/> -->
              
              <body name="l_upper_arm_roll" pos="0 0.067 0" quat="0.976296 -0.216441 0 0">
                <inertial pos="0.01986 0.02608 -0.025535" quat="0.893234 0.357735 0.271874 -0.0156034" mass="0.1786" diaginertia="0.00023545 0.000209436 9.26143e-05"/>
                <!-- <joint name="l_shoulder_roll" pos="0 0 0" axis="1 0 0" range="-0.57 3.27"/> -->
                
                <geom size="0.04" rgba="0.89804 0.91765 0.92941 1"/>
                <body name="l_upper_arm_yaw" pos="0 0.0403814 -0.0572328">
                  <inertial pos="0.00010029 0.0012809 -0.097194" quat="0.999843 0.0176975 -0.000104318 -0.000563119" mass="0.98085" diaginertia="0.00618618 0.00611969 0.000570189"/>
                  <!-- <joint name="l_shoulder_yaw" pos="0 0 0" axis="0 0 1" range="-2.97 2.97"/> -->
                  
                  <geom size="0.03 0.055" pos="0 0 -0.05" type="cylinder" rgba="0.75294 0.75294 0.75294 1"/>
                  <body name="l_lower_arm_pitch" pos="0 0.00125501 -0.188749">
                    <inertial pos="7.6884e-09 0.020584 -0.020113" quat="0.676835 -0.204682 0.204682 0.676835" mass="0.059535" diaginertia="3.12523e-05 2.796e-05 1.40177e-05"/>
                    <!-- <joint name="l_elbow_pitch" pos="0 0 0" axis="0 1 0" range="-2.27 2.27"/> -->
                    
                    <body name="l_hand_yaw" pos="0 0.000299612 -0.0404989">
                      <inertial pos="-0.00048885 0.0013916 -0.08204" quat="0.99956 -0.00194832 -2.05965e-05 0.0296028" mass="1.2684" diaginertia="0.00419493 0.00409086 0.000847261"/>
                      <!-- <joint name="l_wrist_yaw" pos="0 0 0" axis="0 0 1" range="-2.97 2.97"/> -->
                      
                      <geom size="0.035 0.085" pos="0 0 -0.08" type="cylinder" rgba="0.75294 0.75294 0.75294 1"/>
                      <body name="l_hand_roll" pos="0 0.001337 -0.20108">
                        <inertial pos="1.566e-08 -0.00043791 -2.922e-06" quat="0.5 0.5 0.5 0.5" mass="0.0054351" diaginertia="3.6e-07 3.6e-07 7e-08"/>
                        <!-- <joint name="l_wrist_roll" pos="0 0 0" axis="1 0 0" range="-0.96 0.87"/> -->
                        
                        <body name="l_hand_pitch">
                          <inertial pos="0.0058876 -0.0010755 -0.082238" quat="0.813153 0.040279 0.00796725 0.580599" mass="0.54891" diaginertia="0.00152687 0.00108682 0.000582753"/>
                          <!-- <joint name="l_wrist_pitch" pos="0 0 0" axis="0 1 0" range="-0.61 0.61"/> -->
                          
                          <geom size="0.036" pos="0 0 -0.07" rgba="0.75294 0.75294 0.75294 1"/>
                        </body>
                      </body>
                    </body>
                  </body>
                </body>
              </body>
            </body>
            <body name="r_upper_arm_pitch" pos="0 -0.126624 0.219259" quat="0.976296 -0.21644 0 0">
              <inertial pos="0.0054189 -0.058978 0.0001189" quat="0.688371 0.723998 0.033838 0.0287698" mass="0.78809" diaginertia="0.000777007 0.000679609 0.000492064"/>
              <!-- <joint name="r_shoulder_pitch" pos="0 0 0" axis="0 1 0" range="-2.79 1.92"/> -->
              
              <body name="r_upper_arm_roll" pos="0 -0.067 0" quat="0.976296 0.21644 0 0">
                <inertial pos="0.019868 -0.025881 -0.025684" quat="0.89443 -0.354722 0.271831 0.0165736" mass="0.1786" diaginertia="0.000235434 0.000209404 9.26224e-05"/>
                <!-- <joint name="r_shoulder_roll" pos="0 0 0" axis="1 0 0" range="-3.27 0.57"/> -->
                
                <geom size="0.04" rgba="0.89804 0.91765 0.92941 1"/>
                <body name="r_upper_arm_yaw" pos="0 -0.04 -0.0575">
                  <inertial pos="-0.00010032 -0.00063501 -0.097127" quat="0.999896 -0.0143971 0.000111836 0.000334005" mass="0.98085" diaginertia="0.0061732 0.00610683 0.00057023"/>
                  <!-- <joint name="r_shoulder_yaw" pos="0 0 0" axis="0 0 1" range="-2.97 2.97"/> -->
                  
                  <geom size="0.03 0.055" pos="0 0 -0.05" type="cylinder" rgba="0.75294 0.75294 0.75294 1"/>
                  <body name="r_lower_arm_pitch" pos="0 0 -0.18853">
                    <inertial pos="-7.6455e-09 -0.020449 -0.020249" quat="0.676142 0.20696 -0.20696 0.676142" mass="0.059535" diaginertia="3.12637e-05 2.796e-05 1.40163e-05"/>
                    <!-- <joint name="r_elbow_pitch" pos="0 0 0" axis="0 1 0" range="-2.27 2.27"/> -->
                    
                    <body name="r_hand_yaw" pos="0 -3.03303e-05 -0.0405">
                      <inertial pos="0.00048881 -0.00084627 -0.082047" quat="0.999548 0.00527184 -7.7624e-05 0.0295879" mass="1.2684" diaginertia="0.00419493 0.00409087 0.000847259"/>
                      <!-- <joint name="r_wrist_yaw" pos="0 0 0" axis="0 0 1" range="-2.97 2.97"/> -->
                      
                      <geom size="0.035 0.085" pos="0 0 -0.08" type="cylinder" rgba="0.75294 0.75294 0.75294 1"/>
                      <body name="r_hand_roll" pos="0 0 -0.201084">
                        <inertial pos="-1.552e-08 0.00043792 -1.1275e-08" quat="0.5 0.5 0.5 0.5" mass="0.0054351" diaginertia="3.6e-07 3.6e-07 7e-08"/>
                        <!-- <joint name="r_wrist_roll" pos="0 0 0" axis="1 0 0" range="-0.87 0.96"/> -->
                        
                        <body name="r_hand_pitch">
                          <inertial pos="0.0058875 0.0016218 -0.082229" quat="0.580588 0.0098997 0.0375703 0.81327" mass="0.54891" diaginertia="0.00152691 0.00108681 0.000582768"/>
                          <!-- <joint name="r_wrist_pitch" pos="0 0 0" axis="0 1 0" range="-0.61 0.61"/> -->
                          
                          <geom size="0.036" pos="0 0 -0.07" rgba="0.75294 0.75294 0.75294 1"/>
                        </body>
                      </body>
                    </body>
                  </body>
                </body>
              </body>
            </body>
            <body name="link_head_pitch" pos="0.001 -0.000225513 0.305">
              <inertial pos="0.00043792 1.5503e-08 -1.1298e-08" quat="0.707107 0.707107 0 0" mass="0.00543512" diaginertia="3.6e-07 3.6e-07 7e-08"/>
              <!-- <joint name="joint_head_pitch" pos="0 0 0" axis="0 1 0" range="-0.87 0.87"/> -->
              
              <geom size="0.07" pos="0 0 0.1" rgba="0.75294 0.75294 0.75294 1"/>
              <body name="link_head_roll">
                <inertial pos="-0.003976 2.2544e-05 0.015347" quat="0.669576 0.669576 0.227306 -0.227306" mass="0.0713171" diaginertia="3.07787e-05 2.49813e-05 2.039e-05"/>
                <!-- <joint name="joint_head_roll" pos="0 0 0" axis="1 0 0" range="-0.35 0.35"/> -->
                
                <body name="link_head_yaw" pos="0 5.373e-05 0.036">
                  <inertial pos="0.02323 0.00026918 0.11024" quat="0.694627 -0.130794 -0.130531 0.695232" mass="1.38984" diaginertia="0.00988205 0.00835953 0.00593029"/>
                  <!-- <joint name="joint_head_yaw" pos="0 0 0" axis="0 0 1" range="-2.71 2.71"/> -->
                  
                </body>
              </body>
            </body>
          </body>
        </body>
      </body>    
    </body>
  </worldbody>
  <actuator>
    <!-- User parameter is the maximum no-load motor RPM -->
    <motor name="l_hip_roll" joint="l_hip_roll" ctrlrange="-48 48" user="116"/>
    <motor name="l_hip_yaw" joint="l_hip_yaw" ctrlrange="-66 66" user="160"/>
    <motor name="l_hip_pitch" joint="l_hip_pitch" ctrlrange="-225 225" user="357"/>
    <motor name="l_knee_pitch" joint="l_knee_pitch" ctrlrange="-225 225" user="357"/>
    <motor name="l_ankle_pitch" joint="l_ankle_pitch" ctrlrange="-28 28" user="194"/>
    <motor name="l_ankle_roll" joint="l_ankle_roll" ctrlrange="-30 30" user="194"/>
    <motor name="r_hip_roll" joint="r_hip_roll" ctrlrange="-48 48" user="116"/>
    <motor name="r_hip_yaw" joint="r_hip_yaw" ctrlrange="-66 66" user="160"/>
    <motor name="r_hip_pitch" joint="r_hip_pitch" ctrlrange="-225 225" user="357"/>
    <motor name="r_knee_pitch" joint="r_knee_pitch" ctrlrange="-225 225" user="357"/>
    <motor name="r_ankle_pitch" joint="r_ankle_pitch" ctrlrange="-28 28" user="194"/>
    <motor name="r_ankle_roll" joint="r_ankle_roll" ctrlrange="-30 30" user="194"/>
  </actuator>

  <sensor>
    <accelerometer name="accel" site="imu"/>
    <gyro name="gyro" site="imu"/>
  </sensor>
</mujoco>
